Workbook
Name asmClasses: Miscellaneous!$F$25:$G$27
Name asmCosts: Miscellaneous!$AG$29:$AK$31
Name asmSupplier: 'Car Purchase'!$O$33:$P$35
Name bronzePayments: 'Costs (2)'!$L$14:$M$21
Name bronzePayments: Costs!$L$14:$M$21
Name classIndexes: Miscellaneous!$J$4:$K$22
Name driverCosts: 'Costs (2)'!$L$5:$M$7
Name driverCosts: Costs!$L$5:$M$7
Name euemClasses: Miscellaneous!$F$15:$G$17
Name euemCosts: Miscellaneous!$AG$21:$AK$23
Name euemSupplier: 'Car Purchase'!$O$19:$P$21
Name gemClasses: Miscellaneous!$F$5:$G$8
Name gemCosts: Miscellaneous!$AG$5:$AK$8
Name gemSupplier: 'Car Purchase'!$O$7:$P$10
Name modelData: 'Costs (2)'!$B$5:$I$46
Name modelData: Costs!$B$5:$I$41
Name nasccClasses: Miscellaneous!$F$10:$G$13
Name nasccCosts: Miscellaneous!$AG$9:$AK$12
Name nasccEcCosts: Miscellaneous!$AG$17:$AK$20
Name nasccScCosts: Miscellaneous!$AG$13:$AK$16
Name nasccSupplier: 'Car Purchase'!$O$13:$P$16
Name oneOffs: Miscellaneous!$AN$5:$AP$14
Name purchasedCars: 'Car Purchase'!$B$5:$D$49
Name seriesClasses: Miscellaneous!$B$5:$C$13
Name seriesCodeClasses: Miscellaneous!$B$17:$C$23
Name setupCostsAero: Miscellaneous!$AW$9:$AX$11
Name setupCostsChassis: Miscellaneous!$AW$24:$AX$26
Name setupCostsFrontSusp: Miscellaneous!$AW$14:$AX$16
Name setupCostsGeneral: Miscellaneous!$AW$4:$AX$6
Name setupCostsRearSusp: Miscellaneous!$AW$19:$AX$21
Name setupCostsReliability: Miscellaneous!$AW$34:$AX$38
Name setupCostsTyres: Miscellaneous!$AW$29:$AX$31
Name t_asmGT3: Miscellaneous!$R$47:$S$47
Name t_asmGT4: Miscellaneous!$R$49:$S$49
Name t_asmLMP3: Miscellaneous!$R$45:$S$45
Name t_euemLMGTE: Miscellaneous!$R$31:$S$32
Name t_euemLMP2: Miscellaneous!$R$26:$S$27
Name t_euemLMP3: Miscellaneous!$R$29:$S$29
Name t_gemLMGTE: Miscellaneous!$R$11:$S$12
Name t_gemLMP1: Miscellaneous!$R$5:$S$6
Name t_gemLMP2: Miscellaneous!$R$8:$S$9
Name t_nasccDPi: Miscellaneous!$R$14:$S$15
Name t_nasccGTD: Miscellaneous!$R$23:$S$24
Name t_nasccGTLM: Miscellaneous!$R$20:$S$21
Name t_nasccLMP2: Miscellaneous!$R$17:$S$18
Name t_wgtmGT3A: Miscellaneous!$R$41:$S$41
Name t_wgtmGT3P: Miscellaneous!$R$38:$S$39
Name t_wgtmGT4: Miscellaneous!$R$43:$S$43
Name t_wgtssGT3: Miscellaneous!$R$34:$S$34
Name t_wgtssGT4: Miscellaneous!$R$36:$S$36
Name wgtmClasses: Miscellaneous!$F$22:$G$23
Name wgtmCosts: Miscellaneous!$AG$26:$AK$28
Name wgtmSupplier: 'Car Purchase'!$O$28:$P$30
Name wgtssClasses: Miscellaneous!$F$19:$G$20
Name wgtssCosts: Miscellaneous!$AG$24:$AK$25
Name wgtssSupplier: 'Car Purchase'!$O$24:$P$25

Sheet Costs (2)
B2: Team Creator V10 - 2018 | L2: Team Creator V10 - 2018 | P2: Team Creator V10 - 2018 | U2: Team Creator V10 - 2018
B3: Model Name | C3: Platform | D3: Cost ($M) | E3: Spare Chassis ($M) | F3: Spare Engine ($M) | G3: Spares Package ($M) | H3: Maintenance Cost ($M) | I3: Running Cost ($M) | L3: Driver Costs | P3: Tyre Supplier Costs | U3: Series Data
L4: Rank | M4: Cost | P4: Global Endurance Masters | U4: Series Name | V4: Classes | W4: Races | Z4: Race Times (Hrs) | AC4: Entry Cost ($M) | AF4: One Off ($M)
B5: Audi R18 | C5: LMP1-H | D5: 4.8 | E5: 0.85 | F5: 1.15 | G5: 1.1 | H5: 1.75 | I5: 0.375 | L5: Platinum | M5: 0.015 | P5: Class | Q5: Tyre Supplier | R5: Cost Per Race ($M) | U5: Global Endurance Masters | V5: LMP1 | W5: 8 | Z5: 72 | AC5: 2.5 | AF5: 0.35
B6: Porsche 919 Hybrid | C6: LMP1-H | D6: 4.85 | E6: 0.85 | F6: 1.25 | G6: 1.1 | H6: 0.75 | I6: 0.375 | L6: Gold | M6: 0.01 | P6: LMP1 | Q6: Michelin | R6: 0.03 | V6: LMP2 | W6: 8 | Z6: 72 | AC6: 1 | AF6: 0.2
B7: Toyota TS050 Hybrid | C7: LMP1-H | D7: 4.8 | E7: 0.85 | F7: 1.1 | G7: 1 | H7: 0.7 | I7: 0.35 | L7: Silver | M7: 0.005 | P7: LMP2 | Q7: Dunlop | R7: 0.008 | V7: LMGTE PRO | W7: 8 | Z7: 72 | AC7: 2 | AF7: 0.3
B8: ENSO CLM P1/01 | C8: LMP1-L | D8: 2.3 | E8: 0.55 | F8: 0.45 | G8: 0.5 | H8: 0.4 | I8: 0.09 | L8: Bronze | M8: 0 | Q8: Michelin | R8: 0.008 | V8: LMGTE AM | W8: 8 | Z8: 72 | AC8: 1 | AF8: 0.2
B9: Cadillac DPi-V.R | C9: DPi | D9: 1.5 | E9: 0.25 | F9: 0.5 | G9: 0.5 | H9: 0.3 | I9: 0.035 | P9: LMGTE (PRO + AM) | Q9: Dunlop | R9: 0.012 | U9: North American Sportscar Championship | V9: DPi | W9: 10 | X9: 5 | Y9: 5 | Z9: 72 | AA9: 14 | AB9: 58 | AC9: 2 | AD9: 1 | AE9: 1 | AF9: 0.2
B10: Mazda RT24-P | C10: DPi | D10: 1.5 | E10: 0.25 | F10: 0.5 | G10: 0.5 | H10: 0.3 | I10: 0.035 | Q10: Michelin | R10: 0.012 | V10: LMP2 | W10: 9 | X10: 4 | Y10: 5 | Z10: 70 | AA10: 12 | AB10: 58 | AC10: 1.25 | AD10: 0.6 | AE10: 0.75 | AF10: 0.1
B11: Nissan Onroak DPi | C11: DPi | D11: 1.5 | E11: 0.25 | F11: 0.5 | G11: 0.5 | H11: 0.3 | I11: 0.035 | L11: Team Creator V10 - 2018 | P11: NASCC | V11: GTLM | W11: 11 | X11: 6 | Y11: 5 | Z11: 76 | AA11: 18 | AB11: 58 | AC11: 2 | AD11: 1 | AE11: 1 | AF11: 0.2
B12: Dallara P217 | C12: LMP2 | D12: 0.45 | E12: 0.175 | F12: 0.35 | G12: 0.35 | H12: 0.085 | I12: 0.0125 | L12: Bronze Payments | P12: Class | Q12: Tyre Supplier | R12: Cost Per Race ($M) | V12: GTD | W12: 11 | X12: 6 | Y12: 5 | Z12: 75 | AA12: 17 | AB12: 58 | AC12: 1.25 | AD12: 0.6 | AE12: 0.75 | AF12: 0.1
B13: Ligier JS P217 | C13: LMP2 | D13: 0.45 | E13: 0.175 | F13: 0.35 | G13: 0.35 | H13: 0.085 | I13: 0.0125 | L13: Platform | M13: Funding | P13: DPi | Q13: Continental | R13: 0.025 | U13: Eurasian Endurance Masters | V13: LMP2 | W13: 9 | Z13: 36 | AC13: 0.35 | AF13: -
B14: Oreca 07 | C14: LMP2 | D14: 0.45 | E14: 0.175 | F14: 0.35 | G14: 0.35 | H14: 0.085 | I14: 0.0125 | L14: LMP1-H | M14: 0.09 | P14: LMP2 | Q14: Continental | R14: 0.008 | V14: LMP3 | W14: 9 | Z14: 36 | AC14: 0.35 | AF14: -
B15: Riley-Multimatic Mk. 30 | C15: LMP2 | D15: 0.45 | E15: 0.175 | F15: 0.35 | G15: 0.35 | H15: 0.085 | I15: 0.0125 | L15: LMP1-L | M15: 0.07 | Q15: Michelin | R15: 0.008 | V15: LMGTE | W15: 9 | Z15: 36 | AC15: 0.35 | AF15: -
B16: ADESS-03 | C16: LMP3 | D16: 0.21 | E16: 0.08 | F16: 0.02 | G16: 0.15 | H16: 0.05 | I16: 0.01 | L16: DPi | M16: 0.055 | P16: GTLM | Q16: Michelin | R16: 0.014 | U16: World GT Sprint Series | V16: GT3 | W16: 11 | Z16: 22 | AC16: 0.85 | AF16: 0.15
B17: Ginetta-Juno P3 | C17: LMP3 | D17: 0.21 | E17: 0.08 | F17: 0.02 | G17: 0.15 | H17: 0.05 | I17: 0.01 | L17: LMP2 | M17: 0.035 | P17: GTD | Q17: Continental | R17: 0.01 | V17: GT4 | W17: 11 | Z17: 22 | AC17: 0.7 | AF17: 0.15
B18: Ligier JS P3 | C18: LMP3 | D18: 0.21 | E18: 0.08 | F18: 0.02 | G18: 0.15 | H18: 0.05 | I18: 0.01 | L18: LMP3 | M18: 0.025 | P18: EuEM | U18: World GT Masters | V18: GT3-P | W18: 7 | Z18: 93 | AC18: 1.25 | AF18: 0.2
B19: Norma M30 | C19: LMP3 | D19: 0.21 | E19: 0.08 | F19: 0.02 | G19: 0.15 | H19: 0.05 | I19: 0.01 | L19: LMGTE | M19: 0.05 | P19: Class | Q19: Tyre Supplier | R19: Cost Per Race ($M) | V19: GT3-A | W19: 7 | Z19: 93 | AC19: 1 | AF19: 0.2
B20: Aston Martin Vantage GTE | C20: LMGTE | D20: 0.8 | E20: 0.25 | F20: 0.3 | G20: 0.5 | H20: 0.2 | I20: 0.025 | L20: GT3 | M20: 0.035 | P20: LMP2 | Q20: Dunlop | R20: 0.006 | V20: GT4 | W20: 7 | Z20: 93 | AC20: 1 | AF20: 0.2
B21: BMW M6 GTLM | C21: LMGTE | D21: 0.8 | E21: 0.25 | F21: 0.3 | G21: 0.5 | H21: 0.2 | I21: 0.025 | L21: GT4 | M21: 0.025 | Q21: Michelin | R21: 0.006 | U21: American Sportscar Masters | V21: LMP3 | W21: 9 | Z21: 24 | AC21: 0.2 | AF21: -
B22: Chevrolet Corvette C7.R | C22: LMGTE | D22: 0.8 | E22: 0.25 | F22: 0.3 | G22: 0.5 | H22: 0.2 | I22: 0.025 | P22: LMP3 | Q22: Michelin | R22: 0.006 | V22: GT3 | W22: 9 | Z22: 24 | AC22: 0.2 | AF22: -
B23: Ferrari 488 GTE | C23: LMGTE | D23: 0.8 | E23: 0.25 | F23: 0.3 | G23: 0.5 | H23: 0.2 | I23: 0.025 | P23: LMGTE | Q23: Dunlop | R23: 0.007 | V23: GT4 | W23: 9 | Z23: 24 | AC23: 0.2 | AF23: -
B24: Ford GT | C24: LMGTE | D24: 0.8 | E24: 0.25 | F24: 0.3 | G24: 0.5 | H24: 0.2 | I24: 0.025 | Q24: Michelin | R24: 0.007
B25: Porsche 911 RSR | C25: LMGTE | D25: 0.8 | E25: 0.25 | F25: 0.3 | G25: 0.5 | H25: 0.2 | I25: 0.025 | P25: WGTSS
B26: Acura NSX GT3 | C26: GT3 | D26: 0.6 | E26: 0.175 | F26: 0.225 | G26: 0.4 | H26: 0.125 | I26: 0.015 | P26: Class | Q26: Tyre Supplier | R26: Cost Per Race ($M)
B27: Aston Martin V12 Vantage GT3 | C27: GT3 | D27: 0.6 | E27: 0.175 | F27: 0.225 | G27: 0.4 | H27: 0.125 | I27: 0.015 | P27: GT3 | Q27: Dunlop | R27: 0.007
B28: Audi R8 LMS | C28: GT3 | D28: 0.6 | E28: 0.175 | F28: 0.225 | G28: 0.4 | H28: 0.125 | I28: 0.015 | P28: GT4 | Q28: Michelin | R28: 0.005
B29: Bentley Continental GT3 | C29: GT3 | D29: 0.6 | E29: 0.175 | F29: 0.225 | G29: 0.4 | H29: 0.125 | I29: 0.015 | P29: WGTM
B30: BMW M6 GT3 | C30: GT3 | D30: 0.6 | E30: 0.175 | F30: 0.225 | G30: 0.4 | H30: 0.125 | I30: 0.015 | P30: Class | Q30: Tyre Supplier | R30: Cost Per Race ($M)
B31: Callaway Corvette C7 GT3-R | C31: GT3 | D31: 0.6 | E31: 0.175 | F31: 0.225 | G31: 0.4 | H31: 0.125 | I31: 0.015 | P31: GT3-P | Q31: Continental | R31: 0.007
B32: Ferrari 488 GT3 | C32: GT3 | D32: 0.6 | E32: 0.175 | F32: 0.225 | G32: 0.4 | H32: 0.125 | I32: 0.015 | Q32: Dunlop | R32: 0.007
B33: Lamborghini Huracan GT3 | C33: GT3 | D33: 0.6 | E33: 0.175 | F33: 0.225 | G33: 0.4 | H33: 0.125 | I33: 0.015 | P33: GT3-A | Q33: Dunlop | R33: 0.007
B34: Lexus RC F GT3 | C34: GT3 | D34: 0.6 | E34: 0.175 | F34: 0.225 | G34: 0.4 | H34: 0.125 | I34: 0.015 | P34: GT4 | Q34: Michelin | R34: 0.005
B35: McLaren 650S GT3 | C35: GT3 | D35: 0.6 | E35: 0.175 | F35: 0.225 | G35: 0.4 | H35: 0.125 | I35: 0.015 | P35: ASM
B36: Mercedes-AMG GT3 | C36: GT3 | D36: 0.6 | E36: 0.175 | F36: 0.225 | G36: 0.4 | H36: 0.125 | I36: 0.015 | P36: Class | Q36: Tyre Supplier | R36: Cost Per Race ($M)
B37: Porsche 911 GT3 R | C37: GT3 | D37: 0.6 | E37: 0.175 | F37: 0.225 | G37: 0.4 | H37: 0.125 | I37: 0.015 | P37: LMP3 | Q37: Michelin | R37: 0.006
B38: Aston Martin V9 Vantage GT4 | C38: GT4 | D38: 0.4 | E38: 0.2 | F38: 0.175 | G38: 0.25 | H38: 0.075 | I38: 0.01 | P38: GT3 | Q38: Michelin | R38: 0.005
B39: Ekris M4 GT4 | C39: GT4 | D39: 0.4 | E39: 0.2 | F39: 0.175 | G39: 0.25 | H39: 0.075 | I39: 0.01 | P39: GT4 | Q39: Michelin | R39: 0.005
B40: Ford Mustang GT4 | C40: GT4 | D40: 0.4 | E40: 0.2 | F40: 0.175 | G40: 0.25 | H40: 0.075 | I40: 0.01
B41: Ginetta G55 GT4 | C41: GT4 | D41: 0.4 | E41: 0.2 | F41: 0.175 | G41: 0.25 | H41: 0.075 | I41: 0.01
...

Sheet Costs
B2: Team Creator V10 - 2018 | L2: Team Creator V10 - 2018 | P2: Team Creator V10 - 2018 | U2: Team Creator V10 - 2018
B3: Model Name | C3: Platform | D3: Cost ($M) | E3: Spare Chassis ($M) | F3: Spare Engine ($M) | G3: Spares Package ($M) | H3: Maintenance Cost ($M) | I3: Running Cost ($M) | L3: Driver Costs | P3: Tyre Supplier Costs | U3: Series Data
L4: Rank | M4: Cost | P4: Global Endurance Masters | U4: Series Name | V4: Classes | W4: Races | Z4: Race Times (Hrs) | AC4: Entry Cost ($M) | AF4: One Off ($M)
B5: BR Engineering BR1 | C5: LMP1-L | D5: 1.7 | E5: 0.25 | F5: 0.45 | G5: 0.5 | I5: 0.09 | L5: Platinum | M5: 0.015 | P5: Class | Q5: Tyre Supplier | R5: Cost Per Race ($M) | U5: Global Endurance Masters | V5: LMP1 | W5: 8 | Z5: 72 | AC5: 2.5 | AF5: 0.35
B6: ENSO CLM P1/01 | C6: LMP1-L | D6: 2 | E6: 0.45 | F6: 0.45 | G6: 0.5 | H6: 0.4 | I6: 0.09 | L6: Gold | M6: 0.01 | P6: LMP1 | Q6: Dunlop | R6: 0.03 | V6: LMP2 | W6: 8 | Z6: 72 | AC6: 1 | AF6: 0.2
B7: Ginetta G60-LT-P1 | C7: LMP1-L | D7: 1.65 | E7: 0.45 | F7: 0.45 | G7: 0.5 | I7: 0.09 | L7: Silver | M7: 0.005 | Q7: Michelin | R7: 0.03 | V7: LMGTE PRO | W7: 8 | Z7: 72 | AC7: 2 | AF7: 0.3
B8: Rebellion R13 | C8: LMP1-L | D8: 1.9 | E8: 0.25 | F8: 0.45 | G8: 0.5 | I8: 0.09 | L8: Bronze | M8: 0 | P8: LMP2 | Q8: Dunlop | R8: 0.008 | V8: LMGTE AM | W8: 8 | Z8: 72 | AC8: 1 | AF8: 0.2
B9: Porsche 919 Hybrid | C9: LMP1-H | D9: 4.85 | E9: 0.75 | F9: 1.25 | G9: 1.1 | H9: 0.75 | I9: 0.375 | Q9: Michelin | R9: 0.008 | U9: North American Sportscar Championship | V9: DPi | W9: 10 | X9: 5 | Y9: 5 | Z9: 72 | AA9: 14 | AB9: 58 | AC9: 2 | AD9: 1 | AE9: 1 | AF9: 0.2
B10: Toyota TS050 - Hybrid | C10: LMP1-H | D10: 4.8 | E10: 0.75 | F10: 1.15 | G10: 1 | H10: 0.7 | I10: 0.35 | P10: LMGTE (PRO + AM) | Q10: Dunlop | R10: 0.012 | V10: LMP2 | W10: 9 | X10: 4 | Y10: 5 | Z10: 70 | AA10: 12 | AB10: 58 | AC10: 1.25 | AD10: 0.6 | AE10: 0.75 | AF10: 0.1
B11: Acura ARX-05 | C11: DPi | D11: 1.5 | E11: 0.25 | F11: 0.5 | G11: 0.5 | H11: 0.3 | I11: 0.035 | L11: Team Creator V10 - 2018 | Q11: Michelin | R11: 0.012 | V11: GTLM | W11: 11 | X11: 6 | Y11: 5 | Z11: 76 | AA11: 18 | AB11: 58 | AC11: 2 | AD11: 1 | AE11: 1 | AF11: 0.2
B12: Cadillac DPi-V.R | C12: DPi | D12: 1.5 | E12: 0.25 | F12: 0.5 | G12: 0.5 | H12: 0.3 | I12: 0.035 | L12: Bronze Payments | P12: North American Sportscar Championship | V12: GTD | W12: 11 | X12: 6 | Y12: 5 | Z12: 75 | AA12: 17 | AB12: 58 | AC12: 1.25 | AD12: 0.6 | AE12: 0.75 | AF12: 0.1
B13: Mazda RT24-P | C13: DPi | D13: 1.5 | E13: 0.25 | F13: 0.5 | G13: 0.5 | H13: 0.3 | I13: 0.035 | L13: Platform | M13: Funding | P13: Class | Q13: Tyre Supplier | R13: Cost Per Race ($M) | U13: Eurasian Endurance Masters | V13: LMP2 | W13: 9 | Z13: 36 | AC13: 0.35 | AF13: -
B14: Nissan Onroak DPi | C14: DPi | D14: 1.5 | E14: 0.25 | F14: 0.5 | G14: 0.5 | H14: 0.3 | I14: 0.035 | L14: LMP1-H | M14: 0.09 | P14: DPi | Q14: Continental | R14: 0.025 | V14: LMP3 | W14: 9 | Z14: 36 | AC14: 0.35 | AF14: -
B15: Dallara P217 | C15: LMP2 | D15: 0.45 | E15: 0.175 | F15: 0.35 | G15: 0.35 | H15: 0.085 | I15: 0.0125 | L15: LMP1-L | M15: 0.07 | Q15: Michelin | R15: 0.025 | V15: LMGTE | W15: 9 | Z15: 36 | AC15: 0.35 | AF15: -
B16: Ligier JS P217 | C16: LMP2 | D16: 0.45 | E16: 0.175 | F16: 0.35 | G16: 0.35 | H16: 0.085 | I16: 0.0125 | L16: DPi | M16: 0.055 | P16: LMP2 | Q16: Continental | R16: 0.008
B17: Oreca 07 | C17: LMP2 | D17: 0.45 | E17: 0.175 | F17: 0.35 | G17: 0.35 | H17: 0.085 | I17: 0.0125 | L17: LMP2 | M17: 0.035 | Q17: Michelin | R17: 0.008
B18: Riley-Multimatic Mk. 30 | C18: LMP2 | D18: 0.45 | E18: 0.175 | F18: 0.35 | G18: 0.35 | H18: 0.085 | I18: 0.0125 | L18: LMP3 | M18: 0.025 | P18: GTLM | Q18: Continental | R18: 0.014
B19: ADESS-03 | C19: LMP3 | D19: 0.21 | E19: 0.08 | F19: 0.02 | G19: 0.15 | H19: 0.05 | I19: 0.01 | L19: LMGTE | M19: 0.05 | Q19: Michelin | R19: 0.014
B20: Ginetta-Juno P3 | C20: LMP3 | D20: 0.21 | E20: 0.08 | F20: 0.02 | G20: 0.15 | H20: 0.05 | I20: 0.01 | L20: GT3 | M20: 0.035 | P20: GTD | Q20: Continental | R20: 0.01
B21: Ligier JS P3 | C21: LMP3 | D21: 0.21 | E21: 0.08 | F21: 0.02 | G21: 0.15 | H21: 0.05 | I21: 0.01 | L21: GT4 | M21: 0.025 | Q21: Michelin | R21: 0.01
B22: Norma M30 | C22: LMP3 | D22: 0.21 | E22: 0.08 | F22: 0.02 | G22: 0.15 | H22: 0.05 | I22: 0.01 | P22: Eurasian Endurance Masters
B23: Aston Martin Vantage GTE | C23: LMGTE | D23: 0.8 | E23: 0.25 | F23: 0.3 | G23: 0.5 | H23: 0.2 | I23: 0.025 | P23: Class | Q23: Tyre Supplier | R23: Cost Per Race ($M)
B24: BMW M8 GTE | C24: LMGTE | D24: 0.8 | E24: 0.25 | F24: 0.3 | G24: 0.5 | H24: 0.2 | I24: 0.025 | P24: LMP2 | Q24: Dunlop | R24: 0.006
B25: Chevrolet Corvette C7.R | C25: LMGTE | D25: 0.8 | E25: 0.25 | F25: 0.3 | G25: 0.5 | H25: 0.2 | I25: 0.025 | Q25: Michelin | R25: 0.006
B26: Ferrari 488 GTE Evo | C26: LMGTE | D26: 0.8 | E26: 0.25 | F26: 0.3 | G26: 0.5 | H26: 0.2 | I26: 0.025 | P26: LMP3 | Q26: Michelin | R26: 0.006
B27: Ford GT | C27: LMGTE | D27: 0.8 | E27: 0.25 | F27: 0.3 | G27: 0.5 | H27: 0.2 | I27: 0.025 | P27: LMGTE | Q27: Dunlop | R27: 0.007
B28: Porsche 911 RSR | C28: LMGTE | D28: 0.8 | E28: 0.25 | F28: 0.3 | G28: 0.5 | H28: 0.2 | I28: 0.025 | Q28: Michelin | R28: 0.007
B29: Acura NSX GT3 | C29: GT3 | D29: 0.6 | E29: 0.175 | F29: 0.225 | G29: 0.4 | H29: 0.125 | I29: 0.015
B30: Aston Martin Vantage GT3 | C30: GT3 | D30: 0.6 | E30: 0.175 | F30: 0.225 | G30: 0.4 | H30: 0.125 | I30: 0.015
B31: Audi R8 LMS | C31: GT3 | D31: 0.6 | E31: 0.175 | F31: 0.225 | G31: 0.4 | H31: 0.125 | I31: 0.015
B32: Bentley Continental GT3 | C32: GT3 | D32: 0.6 | E32: 0.175 | F32: 0.225 | G32: 0.4 | H32: 0.125 | I32: 0.015
B33: BMW M6 GT3 | C33: GT3 | D33: 0.6 | E33: 0.175 | F33: 0.225 | G33: 0.4 | H33: 0.125 | I33: 0.015
B34: Callaway Corvette C7 GT3-R | C34: GT3 | D34: 0.6 | E34: 0.175 | F34: 0.225 | G34: 0.4 | H34: 0.125 | I34: 0.015
B35: Ferrari 488 GT3 | C35: GT3 | D35: 0.6 | E35: 0.175 | F35: 0.225 | G35: 0.4 | H35: 0.125 | I35: 0.015
B36: Lamborghini Huracán GT3 | C36: GT3 | D36: 0.6 | E36: 0.175 | F36: 0.225 | G36: 0.4 | H36: 0.125 | I36: 0.015
B37: Lexus RC F GT3 | C37: GT3 | D37: 0.6 | E37: 0.175 | F37: 0.225 | G37: 0.4 | H37: 0.125 | I37: 0.015
B38: McLaren 650S GT3 | C38: GT3 | D38: 0.6 | E38: 0.175 | F38: 0.225 | G38: 0.4 | H38: 0.125 | I38: 0.015
B39: Mercedes-AMG GT3 | C39: GT3 | D39: 0.6 | E39: 0.175 | F39: 0.225 | G39: 0.4 | H39: 0.125 | I39: 0.015
B40: Nissan GT-R NISMO GT3 | C40: GT3 | D40: 0.6 | E40: 0.175 | F40: 0.225 | G40: 0.4 | H40: 0.125 | I40: 0.015
B41: Porsche 911 GT3 R | C41: GT3 | D41: 0.6 | E41: 0.175 | F41: 0.225 | G41: 0.4 | H41: 0.125 | I41: 0.015

Sheet Miscellaneous
V2: Team Creator V10 - 2018 | AF2: Team Creator V8 | AW2: Setup Bonuses - General | BA2: Team Creator V10 - 2018 | BF2: Team Creator V10 - 2018 | BK2: Team Creator V10 - 2018 | BP2: Team Creator V10 - 2018
N3: OLD | V3: Tyre Supplier Costs | AA3: Tyre Supplier Costs | AF3: Series Data | AW3: Level | AX3: Cost | BA3: Team Bonuses - General | BF3: Team Bonuses - Front Susp | BK3: Team Bonuses - Chassis | BP3: Team Bonuses - Reliability
B4: Series Name | C4: Classes | F4: GEM | J4: LMP1 | K4: 1 | N4: GEM | O4: LMP1 | R4: GEM | S4: LMP1 | V4: Global Endurance Masters | AA4: Global Endurance Masters | AF4: Series Name | AG4: Classes | AH4: Races | AI4: Race Times | AJ4: Entry Cost ($M) | AK4: One Off ($M) | AN4: Event | AO4: Series | AP4: Length | AS4: Selected Tyre Suppliers | AW4: Level 1 | AX4: 0.5 | BA4: Level | BB4: Bonus | BC4: Cost | BF4: Level | BG4: Bonus | BH4: Cost | BK4: Level | BL4: Bonus | BM4: Cost | BP4: Level | BQ4: Bonus | BR4: Cost
B5: Global Endurance Masters | C5: 1 | F5: LMP1-H | G5: LMP1 | J5: LMP2 | K5: 2 | N5: Dunlop | O5: 0.06 | R5: Dunlop | S5: 0.03 | V5: Class | W5: Tyre Supplier | X5: Cost Per Race ($M) | AA5: Class | AB5: Tyre Supplier | AC5: Cost Per Race ($M) | AF5: Global Endurance Masters | AG5: LMP1 | AH5: 8 | AI5: 72 | AJ5: 2.5 | AK5: 0.35 | AN5: 6 Hours of Spa | AO5: GEM | AP5: 6 | AS5: Global Endurance Masters | AW5: Level 2 | AX5: 0.8 | BA5: Level 1 | BB5: +1-2 | BC5: $500k | BF5: Level 1 | BG5: +1 | BH5: $200k | BK5: Level 1 | BL5: +1-2 | BM5: $300k | BP5: Level 1 | BQ5: +1 | BR5: $200k
B6: North American Sportscar Championship | C6: 2 | F6: LMP1-L | G6: LMP1 | J6: LMGTE PRO | K6: 3 | N6: Michelin | O6: 0.06 | R6: Michelin | S6: 0.03 | V6: LMP1 | W6: Dunlop | X6: 0.03 | AA6: LMP1 | AB6: Michelin | AC6: 0.06 | AG6: LMP2 | AH6: 8 | AI6: 72 | AJ6: 1 | AK6: 0.2 | AN6: 24 Heures du Mans | AO6: GEM | AP6: 24 | AS6: Class | AT6: Tyre Supplier | AW6: Level 3 | AX6: 1.5 | BA6: Level 2 | BB6: +2-3 | BC6: $800k | BF6: Level 2 | BG6: +2-3 | BH6: $450k | BK6: Level 2 | BL6: +2-3 | BM6: $500k | BP6: Level 2 | BQ6: +2 | BR6: $400k
B7: North American Sportscar Championship - SC | C7: 2.1 | F7: LMP2 | G7: LMP2 | J7: LMGTE AM | K7: 4 | N7: GEM | O7: LMP2 | R7: GEM | S7: LMP2 | W7: Michelin | X7: 0.03 | AA7: LMP2 | AB7: Dunlop | AC7: 0.01 | AG7: LMGTE PRO | AH7: 8 | AI7: 72 | AJ7: 2 | AK7: 0.3 | AN7: Rolex 24 at Daytona | AO7: NASCC | AP7: 24 | AS7: LMP1 | AW7: Setup Bonuses - Aero | BA7: Level 3 | BB7: +4-6 | BC7: $1.5m | BF7: Level 3 | BG7: +3-5 | BH7: $800k | BK7: Level 3 | BL7: +4-6 | BM7: $850k | BP7: Level 3 | BQ7: +3 | BR7: $600k
B8: North American Sportscar Championship - EC | C8: 2.2 | F8: LMGTE | G8: LMGTE PRO | J8: DPi | K8: 1 | N8: Dunlop | O8: 0.01 | R8: Dunlop | S8: 0.008 | V8: LMP2 | W8: Dunlop | X8: 0.008 | AB8: Michelin | AC8: 0.0075 | AG8: LMGTE AM | AH8: 8 | AI8: 72 | AJ8: 1 | AK8: 0.2 | AN8: 12 Hours of Sebring | AO8: NASCC | AP8: 12 | AS8: LMP2 | AW8: Level | AX8: Cost | BP8: Level 4 | BQ8: +4 | BR8: $850k
B9: Eurasian Endurance Masters | C9: 3 | F9: NASCC | J9: LMP2 | K9: 2 | N9: Michelin | O9: 0.0075 | R9: Michelin | S9: 0.008 | W9: Michelin | X9: 0.008 | AA9: LMGTE (PRO + AM) | AB9: Dunlop | AC9: 0.02 | AF9: North American Sportscar Championship | AG9: DPi | AH9: 10 | AI9: =AI13 + AI17 -> 72 | AJ9: 2 | AK9: 0.2 | AN9: Petit Le Mans | AO9: NASCC | AP9: 10 | AS9: LMGTE PRO | AW9: Level 1 | AX9: 0.3 | BP9: Level 5 | BQ9: +5 | BR9: $1.1m
B10: World GT Sprint Series | C10: 4 | F10: DPi | G10: DPi | J10: GTLM | K10: 3 | N10: GEM | O10: LMGTE | R10: GEM | S10: LMGTE | V10: LMGTE (PRO + AM) | W10: Dunlop | X10: 0.012 | AB10: Michelin | AC10: 0.02 | AG10: LMP2 | AH10: 8 | AI10: =AI14 + AI18 -> 70 | AJ10: 1.25 | AK10: 0.1 | AN10: World GT Sprint Series at Le Mans | AO10: WGTSS | AP10: 2 | AS10: LMGTE AM | AW10: Level 2 | AX10: 0.5 | BA10: Team Creator V10 - 2018 | BF10: Team Creator V10 - 2018 | BK10: Team Creator V10 - 2018
B11: World GT Masters | C11: 5 | F11: LMP2 | G11: LMP2 | J11: GTD | K11: 4 | N11: Dunlop | O11: 0.02 | R11: Dunlop | S11: 0.012 | W11: Michelin | X11: 0.012 | AA11: NASCC | AG11: GTLM | AH11: 11 | AI11: =AI15 + AI19 -> 76 | AJ11: 2 | AK11: 0.2 | AN11: Bathurst 12 Hours | AO11: WGTM | AP11: 12 | AS11: NASCC | AW11: Level 3 | AX11: 0.85 | BA11: Team Bonuses - Aero | BF11: Team Bonuses - Rear Susp | BK11: Team Bonuses - Tyres
B12: World Prototype Challenge | C12: 6 | F12: LMGTE | G12: GTLM | J12: LMP2 | K12: 1 | N12: Michelin | O12: 0.02 | R12: Michelin | S12: 0.012 | V12: North American Sportscar Championship | AA12: Class | AB12: Tyre Supplier | AC12: Cost Per Race ($M) | AG12: GTD | AH12: 11 | AI12: =AI16 + AI20 -> 75 | AJ12: 1.2 | AK12: 0.1 | AN12: 24 Hours of The Nurburgring | AO12: WGTM | AP12: 24 | AS12: Class | AT12: Tyre Supplier | AW12: Setup Bonuses - Front Susp | BA12: Level | BB12: Bonus | BC12: Cost | BF12: Level | BG12: Bonus | BH12: Cost | BK12: Level | BL12: Bonus | BM12: Cost
B13: American Sportscar Masters | C13: 7 | F13: GT3 | G13: GTD | J13: LMP3 | K13: 2 | N13: NASCC | O13: DPi | R13: NASCC | S13: DPi | V13: Class | W13: Tyre Supplier | X13: Cost Per Race ($M) | AA13: DPi | AB13: Continental | AC13: 0.045 | AF13: North American Sportscar Championship Sprint Cup | AG13: DPi | AH13: 5 | AI13: 14 | AJ13: 1 | AK13: 0.2 | AN13: 24 Hours of Spa | AO13: WGTM | AP13: 24 | AS13: DPi | AW13: Level | AX13: Cost | BA13: Level 1 | BB13: +1-2 | BC13: $300k | BF13: Level 1 | BG13: +1 | BH13: $200k | BK13: Level 1 | BL13: +1 | BM13: $350k
F14: EuEM | J14: LMGTE | K14: 3 | N14: Continental | O14: 0.045 | R14: Continental | S14: 0.025 | V14: DPi | W14: Continental | X14: 0.025 | AA14: LMP2 | AB14: Continental | AC14: 0.01 | AG14: LMP2 | AH14: 4 | AI14: 12 | AJ14: 0.6 | AK14: 0.1 | AN14: ASM 210 Minutes of CoTA | AO14: ASM | AP14: 3 | AS14: LMP2 | AW14: Level 1 | AX14: 0.2 | BA14: Level 2 | BB14: +2-3 | BC14: $500k | BF14: Level 2 | BG14: +2-3 | BH14: $450k | BK14: Level 2 | BL14: +2 | BM14: $600k
F15: LMP2 | G15: LMP2 | J15: GT3 | K15: 1 | N15: NASCC | O15: LMP2 | R15: Michelin | S15: 0.025 | W15: Michelin | X15: 0.025 | AB15: Michelin | AC15: 0.01 | AG15: GTLM | AH15: 6 | AI15: 18 | AJ15: 1 | AK15: 0.2 | AS15: GTLM | AW15: Level 2 | AX15: 0.45 | BA15: Level 3 | BB15: +4-6 | BC15: $850k | BF15: Level 3 | BG15: +3-5 | BH15: $800k | BK15: Level 3 | BL15: +3-4 | BM15: $1m
B16: Series Name | C16: Classes | F16: LMP3 | G16: LMP3 | J16: GT4 | K16: 2 | N16: Continental | O16: 0.01 | R16: NASCC | S16: LMP2 | V16: LMP2 | W16: Continental | X16: 0.008 | AA16: GTLM | AB16: Michelin | AC16: 0.025 | AG16: GTD | AH16: 6 | AI16: 17 | AJ16: 0.6 | AK16: 0.1 | AS16: GTD | AW16: Level 3 | AX16: 0.8
B17: GEM | C17: 1 | F17: LMGTE | G17: LMGTE | J17: GT3-P | K17: 1 | N17: Michelin | O17: 0.01 | R17: Continental | S17: 0.008 | W17: Michelin | X17: 0.008 | AA17: GTD | AB17: Continental | AC17: 0.015 | AF17: North American Sportscar Championship Endurance Cup | AG17: DPi | AH17: 5 | AI17: 58 | AJ17: 1 | AK17: 0.2 | AS17: EuEM | AW17: Setup Bonuses - Rear Susp
B18: NASCC | C18: 2 | F18: WGTSS | J18: GT3-A | K18: 2 | N18: NASCC | O18: GTLM | R18: Michelin | S18: 0.008 | V18: GTLM | W18: Continental | X18: 0.014 | AA18: EuEM | AG18: LMP2 | AH18: 5 | AI18: 58 | AJ18: 0.75 | AK18: 0.1 | AS18: Class | AT18: Tyre Supplier | AW18: Level | AX18: Cost
B19: EuEM | C19: 3 | F19: GT3 | G19: GT3 | J19: GT4 | K19: 3 | N19: Michelin | O19: 0.025 | R19: NASCC | S19: GTLM | W19: Michelin | X19: 0.014 | AA19: Class | AB19: Tyre Supplier | AC19: Cost Per Race ($M) | AG19: GTLM | AH19: 5 | AI19: 58 | AJ19: 1 | AK19: 0.2 | AS19: LMP2 | AW19: Level 1 | AX19: 0.2
B20: WGTSS | C20: 4 | F20: GT4 | G20: GT4 | J20: LMP3 | K20: 1 | N20: NASCC | O20: GTD | R20: Continental | S20: 0.014 | V20: GTD | W20: Continental | X20: 0.01 | AA20: LMP2 | AB20: Dunlop | AC20: 0.01 | AG20: GTD | AH20: 5 | AI20: 58 | AJ20: 0.75 | AK20: 0.1 | AS20: LMP3 | AT20: Michelin | AW20: Level 2 | AX20: 0.45
B21: WGTM | C21: 5 | F21: WGTM | J21: GT3 | K21: 2 | N21: Continental | O21: 0.015 | R21: Michelin | S21: 0.014 | W21: Michelin | X21: 0.01 | AB21: Michelin | AC21: 0.0075 | AF21: Eurasian Endurance Masters | AG21: LMP2 | AH21: 9 | AI21: 36 | AJ21: 0.35 | AK21: 0 | AS21: LMGTE | AW21: Level 3 | AX21: 0.8
B22: WPC | C22: 6 | F22: GT3 | G22: GT3-P | J22: GT4 | K22: 3 | N22: EuEM | O22: LMP2 | R22: NASCC | S22: GTD | V22: Eurasian Endurance Masters | AA22: LMP3 | AB22: Michelin | AC22: 0.01 | AG22: LMP3 | AH22: 9 | AI22: 36 | AJ22: 0.35 | AK22: 0 | AS22: WGTSS | AW22: Setup Bonuses - Chassis
B23: ASM | C23: 7 | F23: GT4 | G23: GT4 | N23: Dunlop | O23: 0.01 | R23: Michelin | S23: 0.01 | V23: Class | W23: Tyre Supplier | X23: Cost Per Race ($M) | AA23: LMGTE | AB23: Dunlop | AC23: 0.015 | AG23: LMGTE | AH23: 9 | AI23: 36 | AJ23: 0.35 | AK23: 0 | AS23: Class | AT23: Tyre Supplier | AW23: Level | AX23: Cost
F24: ASM | N24: Michelin | O24: 0.0075 | R24: Continental | S24: 0.01 | V24: LMP2 | W24: Dunlop | X24: 0.006 | AB24: Michelin | AC24: 0.015 | AF24: World GT Sprint Series | AG24: GT3 | AH24: 11 | AI24: 22 | AJ24: 0.75 | AK24: 0.15 | AS24: GT3 | AT24: Dunlop | AW24: Level 1 | AX24: 0.3
F25: LMP3 | G25: LMP3 | N25: EuEM | O25: LMP3 | R25: EuEM | S25: LMP2 | W25: Michelin | X25: 0.006 | AA25: WGTSS | AG25: GT4 | AH25: 11 | AI25: 22 | AJ25: 0.7 | AK25: 0.15 | AS25: GT4 | AT25: Michelin | AW25: Level 2 | AX25: 0.5
C26: LMP1 | F26: GT3 | G26: GT3 | N26: Michelin | O26: 0.01 | R26: Dunlop | S26: 0.006 | V26: LMP3 | W26: Michelin | X26: 0.006 | AA26: Class | AB26: Tyre Supplier | AC26: Cost Per Race ($M) | AF26: World GT Masters | AG26: GT3-P | AH26: 7 | AI26: 93 | AJ26: 1.25 | AK26: 0.2 | AS26: WGTM | AW26: Level 3 | AX26: 0.85
C27: DPi | F27: GT4 | G27: GT4 | N27: EuEM | O27: LMGTE | R27: Michelin | S27: 0.006 | V27: LMGTE | W27: Dunlop | X27: 0.007 | AA27: GT3 | AB27: Dunlop | AC27: 0.01 | AG27: GT3-A | AH27: 7 | AI27: 93 | AJ27: 1 | AK27: 0.2 | AS27: Class | AT27: Tyre Supplier | AW27: Setup Bonuses - Tyres
C28: LMP2 | N28: Dunlop | O28: 0.015 | R28: EuEM | S28: LMP3 | W28: Michelin | X28: 0.007 | AA28: GT4 | AB28: Michelin | AC28: 0.0075 | AG28: GT4 | AH28: 7 | AI28: 93 | AJ28: 1 | AK28: 0.2 | AS28: GT3-P | AW28: Level | AX28: Cost
C29: LMP3 | N29: Michelin | O29: 0.015 | R29: Michelin | S29: 0.006 | AA29: WGTM | AF29: American Sportscar Masters | AG29: LMP3 | AH29: 9 | AI29: 24 | AJ29: 0.2 | AK29: 0 | AS29: GT3-A | AT29: Dunlop | AW29: Level 1 | AX29: 0.35
C30: GTE | N30: WGTSS | O30: GT3 | R30: EuEM | S30: LMGTE | AA30: Class | AB30: Tyre Supplier | AC30: Cost Per Race ($M) | AG30: GT3 | AH30: 9 | AI30: 24 | AJ30: 0.2 | AK30: 0 | AS30: GT4 | AT30: Michelin | AW30: Level 2 | AX30: 0.6
C31: GT3 | N31: Dunlop | O31: 0.01 | R31: Dunlop | S31: 0.007 | AA31: GT3-P | AB31: Continental | AC31: 0.01 | AG31: GT4 | AH31: 9 | AI31: 24 | AJ31: 0.2 | AK31: 0 | AS31: ASM | AW31: Level 3 | AX31: 1
C32: GT4 | N32: WGTSS | O32: GT4 | R32: Michelin | S32: 0.007 | AB32: Dunlop | AC32: 0.01 | AS32: Class | AT32: Tyre Supplier | AW32: Setup Bonuses - Reliability
N33: Michelin | O33: 0.0075 | R33: WGTSS | S33: GT3 | AA33: GT3-A | AB33: Dunlop | AC33: 0.01 | AS33: LMP3 | AT33: Michelin | AW33: Level | AX33: Cost
N34: WGTM | O34: GT3-P | R34: Dunlop | S34: 0.01 | AA34: GT4 | AB34: Michelin | AC34: 0.0075 | AS34: GT3 | AT34: Michelin | AW34: Level 1 | AX34: 0.2
N35: Continental | O35: 0.01 | R35: WGTSS | S35: GT4 | AA35: ASM | AS35: GT4 | AT35: Michelin | AW35: Level 2 | AX35: 0.4
N36: Dunlop | O36: 0.01 | R36: Michelin | S36: 0.0075 | AA36: Class | AB36: Tyre Supplier | AC36: Cost Per Race ($M) | AW36: Level 3 | AX36: 0.6
N37: WGTM | O37: GT3-A | R37: WGTM | S37: GT3-P | AA37: LMP3 | AB37: Michelin | AC37: 0.01 | AW37: Level 4 | AX37: 0.85
N38: Dunlop | O38: 0.01 | R38: Continental | S38: 0.01 | AA38: GT3 | AB38: Michelin | AC38: 0.01 | AW38: Level 5 | AX38: 1.1
N39: WGTM | O39: GT4 | R39: Dunlop | S39: 0.01 | AA39: GT4 | AB39: Michelin | AC39: 0.01
N40: Michelin | O40: 0.0075 | R40: WGTM | S40: GT3-A
N41: ASM | O41: LMP3 | R41: Dunlop | S41: 0.01
...

Sheet Series + Driver Rules
B2: Team Creator V10 - 2018 | F2: Global Endurance Masters | P2: North American Sportscar Championship (Rolex 24 Driver is Completely Free Choice) | Z2: Eurasian Endurance Masters
B3: Driver Rules
B4: Teams may Enter a Maximum of 3 Classes for a Given Series, with the exception of the Global Endurance Masters, where the limit is 2 Classes. | F4: Series Abbreviation | L4: GEM | P4: Series Abbreviation | V4: NASCC | Z4: Series Abbreviation | AF4: EuEM
F5: Class | G5: Platform | H5: Tyres | J5: Max Entries | K5: Lineup Composition | P5: Class | Q5: Platform | R5: Tyres | T5: Max Entries | U5: Lineup Composition | Z5: Class | AA5: Platform | AB5: Tyres | AD5: Max Entries | AE5: Lineup Composition
B6: Lineups may contain AT MOST 1 Bronze Driver (This Requirement is waived in the LMP2 and GTD Classes for the Rolex 24 4th Driver Slot) | F6: LMP1 | G6: LMP1 | H6: Dunlop | I6: Michelin | J6: 2 | K6: Pro | L6: Free (No Bronzes) | P6: DPi | Q6: DPi | R6: Continental | S6: Michelin | T6: 2 | U6: Pro | V6: Free (NB) | W6: Free | Z6: LMP2 | AA6: LMP2 | AB6: Dunlop | AC6: Michelin | AD6: 2 | AE6: Pro | AF6: Free (NB) | AG6: Silver
F7: LMP2 | G7: LMP2 | H7: Dunlop | I7: Michelin | J7: 2 | K7: Pro | L7: Free | M7: Silver | P7: LMP2 | Q7: LMP2 | R7: Continental | S7: Michelin | T7: 2 | U7: Gold | V7: Bronze | W7: Silver | Z7: LMP3 | AA7: LMP3 | AB7: Michelin | AD7: 2 | AE7: Free | AF7: Silver | AG7: Bronze
B8: Events denoted by a Gold Strip in the Calendars Page allow Teams to apply for Up to 2 Additional Entries per Class. All Other One Off Events only permit 1 Additional Entry per Class. | C8: Max Class Entries for each Class are outlined under 'Max Entries'. | F8: LMGTE PRO | G8: LMGTE | H8: Dunlop | I8: Michelin | J8: 2 | K8: Pro | L8: Free (No Bronzes) | P8: GTLM | Q8: LMGTE | R8: Continental | S8: Michelin | T8: 2 | U8: Pro | V8: Free (NB) | W8: Free | Z8: LMGTE | AA8: LMGTE | AB8: Dunlop | AC8: Michelin | AD8: 2 | AE8: Pro | AF8: Silver | AG8: Bronze
F9: LMGTE AM | G9: LMGTE | H9: Dunlop | I9: Michelin | J9: 2 | K9: Pro | L9: Silver | M9: Bronze | P9: GTD | Q9: GT3 | R9: Continental | S9: Michelin | T9: 2 | U9: Pro | V9: Bronze | W9: Silver
C10: Where a Grading is listed, that is the Highest Driver Grading permitted for that Seat on a Crew. Free means any Grading can be chosen. Certain Classes ban the use of Bronze Drivers.
B13: Teams may Apply for up to 3 Additional Entries for any given Event. Unless an Invite has been received. This increases to 4 Entries for an Event with a Gold Strip
C14: A Designation of 'Pro' means the selected Driver for that seat must either be a Platinum or a Gold Ranked Driver.
B17: The Rolex 24 at Daytona is the only Event that permits 4th Drivers, these are Mandatory in LMP2 and GTD, however are optional in DPi and GTLM. | C17: Bronze Drivers may never be Signed to the Driver 1 Seat.
C19: The 'LMP1' platform encompasses both LMP1-H, and LMP1-L

Sheet Series + Driver Rules (2)
B2: Team Creator V10 - 2018 | F2: Global Endurance Masters | O2: Eurasian Endurance Masters | X2: World GT Sprint Series
B3: Driver Rules
B4: Teams may Enter a Maximum of 3 Classes for a Given Series, with the exception of the Global Endurance Masters, where the limit is 2 Classes. | F4: Series Abbreviation | K4: GEM | O4: Series Abbreviation | T4: EuEM | X4: Series Abbreviation
F5: Class | G5: Platform | H5: Tyres | I5: Max Entries | J5: Lineup Composition | O5: Class | P5: Platform | Q5: Tyres | R5: Max Entries | S5: Lineup Composition | X5: Class | Y5: Platform | Z5: Tyres | AA5: Max Entries | AB5: Lineup Composition
B6: Lineups may contain AT MOST 1 Bronze Driver (This Requirement is waived in the LMP2 and GTD Classes for the Rolex 24 4th Driver Slot) | F6: LMP1 | G6: LMP1 | H6: Michelin | I6: 2 | J6: Pro | K6: Free (No Bronzes) | O6: LMP2 | P6: LMP2 | Q6: Free | R6: 2 | S6: Pro | T6: Free (NB) | U6: Silver | X6: GT3 | Y6: GT3 | Z6: Michelin | AA6: 3 | AB6: Pro | AC6: Silver
F7: LMP2 | G7: LMP2 | H7: Free | I7: 2 | J7: Pro | K7: Free | L7: Silver | O7: LMP3 | P7: LMP3 | Q7: Michelin | R7: 2 | S7: Free | T7: Silver | U7: Bronze | X7: GT4 | Y7: GT4 | Z7: Michelin | AA7: 3 | AB7: Gold | AC7: Bronze
B8: Events denoted by a Gold Strip in the Calendars Page allow Teams to apply for Up to 2 Additional Entries per Class. All Other One Off Events only permit 1 Additional Entry per Class. | C8: Max Class Entries for each Class are outlined under 'Max Entries'. | F8: LMGTE PRO | G8: LMGTE | H8: Free | I8: 2 | J8: Pro | K8: Free (No Bronzes) | O8: LMGTE | P8: LMGTE | Q8: Free | R8: 2 | S8: Pro | T8: Silver | U8: Bronze
F9: LMGTE AM | G9: LMGTE | H9: Free | I9: 2 | J9: Pro | K9: Silver | L9: Bronze
C10: Where a Grading is listed, that is the Highest Driver Grading permitted for that Seat on a Crew. Free means any Grading can be chosen. Certain Classes ban the use of Bronze Drivers.
F12: North American Sportscar Championship (Rolex 24 Driver is Completely Free Choice) | O12: World GT Masters | X12: American Sportscar Masters
B13: Teams may Apply for up to 3 Additional Entries for any given Event. Unless an Invite has been received. This increases to 4 Entries for an Event with a Gold Strip
C14: A Designation of 'Pro' means the selected Driver for that seat must either be a Platinum or a Gold Ranked Driver. | F14: Series Abbreviation | K14: NASCC | O14: Series Abbreviation | T14: WGTM | X14: Series Abbreviation
F15: Class | G15: Platform | H15: Tyres | I15: Max Entries | J15: Lineup Composition | O15: Class | P15: Platform | Q15: Tyres | R15: Max Entries | S15: Lineup Composition | X15: Class | Y15: Platform | Z15: Tyres | AA15: Max Entries | AB15: Lineup Composition
F16: DPi | G16: DPi | H16: Michelin | I16: 2 | J16: Pro | K16: Free (NB) | L16: Free | O16: GT3-P | P16: GT3 | Q16: Free | R16: 3 | S16: Pro | T16: Free (No Bronzes) | X16: LMP3 | Y16: LMP3 | Z16: Michelin | AA16: 2 | AB16: Gold | AC16: Bronze
B17: The Rolex 24 at Daytona is the only Event that permits 4th Drivers, these are Mandatory in LMP2 and GTD, however are optional in DPi and GTLM. | C17: Bronze Drivers may never be Signed to the Driver 1 Seat. | F17: LMP2 | G17: LMP2 | H17: Free | I17: 2 | J17: Gold | K17: Bronze | L17: Silver | O17: GT3-A | P17: GT3 | Q17: Michelin | R17: 3 | S17: Pro | T17: Silver | U17: Bronze | X17: GT3 | Y17: GT3 | Z17: Michelin | AA17: 2 | AB17: Pro | AC17: Bronze
F18: GTLM | G18: LMGTE | H18: Michelin | I18: 2 | J18: Pro | K18: Free (NB) | L18: Free | O18: GT4 | P18: GT4 | Q18: Michelin | R18: 3 | S18: Gold | T18: Silver | U18: Bronze | X18: GT4 | Y18: GT4 | Z18: Michelin | AA18: 2 | AB18: Gold | AC18: Bronze
C19: The 'LMP1' platform encompasses both LMP1-H, and LMP1-L | F19: GTD | G19: GT3 | H19: Michelin | I19: 2 | J19: Pro | K19: Bronze | L19: Silver

Sheet Calendars
B2: Team Creator V10 - 2018 | H2: Team Creator V10 - 2018 | R2: Team Creator V10 - 2018 | AC2: Team Creator V10 - 2018 | AL2: Team Creator V10 - 2018 | AU2: Team Creator V10 - 2018 | BE2: Team Creator V10 - 2018
B3: Permitted One Off Entries | H3: Series Calendar | L3: Global Endurance Masters | R3: Series Calendar | W3: North American Sportscar Championship | AC3: Series Calendar | AG3: Eurasian Endurance Masters | AL3: Series Calendar | AP3: World GT Sprint Series | AU3: Series Calendar | AY3: World GT Masters | BE3: Series Calendar | BI3: American Sportscar Masters
B4: Rd No | C4: Title | E4: Notes | H4: Rd No | I4: Title | K4: Track | M4: Length | N4: Points | O4: Date | R4: Rd No | S4: Title | U4: Track | W4: Length | X4: Points | Y4: Classes | Z4: Date | AC4: Rd No | AD4: Title | AF4: Track | AH4: Length | AI4: Date | AL4: Rd No | AM4: Title | AO4: Track | AQ4: Length | AR4: Date | AU4: Rd No | AV4: Title | AX4: Track | AZ4: Length | BA4: Points | BB4: Date | BE4: Rd No | BF4: Title | BH4: Track | BJ4: Length | BK4: Date
B5: GEM | D5: 24 Heures du Mans | E5: Invite + Application | H5: R1 | J5: 8 Hours of Silverstone | K5: Silverstone Circuit | L5: Great Britain | M5: 8 Hours | N5: B | O5: April 15 | R5: R1 | T5: Rolex 24 at Daytona | U5: Daytona International Speedway | V5: United States | W5: 24 Hours | X5: R24, EC | Y5: All | Z5: Jan 27-28 | AC5: R1 | AE5: 4 Hours of Buriram | AF5: Buriram International Circuit | AG5: Thailand | AH5: 4 Hours | AI5: Jan 14 | AL5: R1 | AN5: World GT Sprint Series at Sepang | AO5: Sepang International Circuit | AP5: Malaysia | AQ5: 90 Mins | AR5: Mar 5 | AU5: R1 | AW5: Bathurst 12 Hours | AX5: Mount Panorama | AY5: Australia | AZ5: 12 Hours | BA5: B | BB5: Feb 5 | BE5: R1 | BG5: ASM 150 Minutes of VIR | BH5: Virginia International Raceway | BI5: United States | BJ5: 150 Mins | BK5: Apr 2
B6: NASCC | D6: Rolex 24 at Daytona | E6: Application | H6: R2 | J6: 6 Hours of Spa | K6: Circuit de Spa-Francorshamps | L6: Belgium | M6: 6 Hours | N6: B | O6: May 5 | R6: R2 | T6: 12 Hours of Sebring | U6: Sebring International Raceway | V6: United States | W6: 12 Hours | X6: E, EC | Y6: All | Z6: March 18 | AC6: R2 | AE6: 4 Hours of The Bend | AF6: The Bend Motorsports Park | AG6: Australia | AH6: 4 Hours | AI6: Feb 25 | AL6: R2 | AN6: World GT Sprint Series at Shanghai | AO6: Shanghai International Circuit | AP6: China | AQ6: 90 Mins | AR6: Mar 26 | AU6: R2 | AW6: 8 Hours of Road America | AX6: Road America | AY6: United States | AZ6: 8 Hours | BA6: B | BB6: Apr 9 | BE6: R2 | BG6: ASM 150 Minutes of Sebring | BH6: Sebring International Raceway | BI6: United States | BJ6: 150 Mins | BK6: May 7
B7: NASCC | D7: 12 Hours of Sebring | E7: Application | H7: R3 | J7: 24 Heures du Mans | K7: Circuit de la Sarthe | L7: France | M7: 24 Hours | N7: A | O7: June 16-17 | R7: R3 | T7: Acura Grand Prix of Long Beach | U7: Streets of Long Beach | V7: United States | W7: 100 Mins | X7: S | Y7: DPi, GTD | Z7: April 7 | AC7: R3 | AE7: 4 Hours of Silverstone | AF7: Silverstone Circuit | AG7: Great Britain | AH7: 4 Hours | AI7: April 14 | AL7: R3 | AN7: World GT Sprint Series at Laguna Seca | AO7: WeatherTech Raceway Laguna Seca | AP7: United States | AQ7: 90 Mins | AR7: Apr 30 | AU7: R3 | AW7: 24 Hours of The Nurburgring | AX7: Nurburgring Nordschleiffe | AY7: Germany | AZ7: 24 Hours | BA7: A | BB7: May 28 | BE7: R3 | BG7: ASM 150 Minutes of Daytona | BH7: Daytona International Speedway | BI7: United States | BJ7: 150 Mins | BK7: May 21
B8: NASCC | D8: Petit Le Mans | E8: Application | H8: R4 | J8: 8 Hours of The Nurburgring | K8: Nurburgring | L8: Germany | M8: 8 Hours | N8: B | O8: July 15 | R8: R4 | T8: Mexico City Grand Prix | U8: Autodromo Hermanos Rodriguez | V8: Mexico | W8: 160 Mins | X8: S | Y8: All | Z8: April 29 | AC8: R4 | AE8: 4 Hours of Paul Ricard | AF8: Circuit Paul Ricard | AG8: France | AH8: 4 Hours | AI8: May 13 | AL8: R4 | AN8: World GT Sprint Series at Circuit Zolder | AO8: Circuit Zolder | AP8: Netherlands | AQ8: 90 Mins | AR8: Jun 4 | AU8: R4 | AW8: 24 Hours of Spa | AX8: Circuit de Spa-Francorshamps | AY8: Belgium | AZ8: 24 Hours | BA8: A | BB8: Jul 30 | BE8: R4 | BG8: ASM 150 Minutes of Laguna Seca | BH8: WeatherTech Raceway Laguna Seca | BI8: United States | BJ8: 150 Mins | BK8: Jun 25
H9: R5 | J9: Lonestar Le Mans | K9: Circuit of The Americas | L9: United States | M9: 6 Hours | N9: B | O9: Sept 9 | R9: R5 | T9: Michelin Grand Prix at VIR | U9: Virginia International Raceway | V9: United States | W9: 160 Mins | X9: S | Y9: LMP2, GT | Z9: May 20 | AC9: R5 | AE9: 4 Hours of Imola | AF9: Imola Circuit | AG9: Italy | AH9: 4 Hours | AI9: June 24 | AL9: R5 | AN9: World GT Sprint Series at Le Mans | AO9: Circuit de la Sarthe | AP9: France | AQ9: 2 Hrs | AR9: Jun 16 | AU9: R5 | AW9: 8 Hours of Indianapolis | AX9: Indianapolis Motor Speedway RC | AY9: United States | AZ9: 8 Hours | BA9: B | BB9: Aug 27 | BE9: R5 | BG9: ASM 150 Minutes of CTMP | BH9: Canadian Tire Motorsport Park | BI9: Canada | BJ9: 150 Mins | BK9: Jul 16
H10: R6 | J10: 6 Hours of Kyalami | K10: Kyalami Circuit | L10: South Africa | M10: 6 Hours | N10: B | O10: Oct 7 | R10: R6 | T10: Sahlen's 6 Hours of The Glen | U10: Watkins Glen International | V10: United States | W10: 6 Hours | X10: E, EC | Y10: All | Z10: July 1 | AC10: R6 | AE10: 4 Hours of Aragon | AF10: Motorland Aragon | AG10: Spain | AH10: 4 Hours | AI10: Aug 5 | AL10: R6 | AN10: World GT Sprint Series at Donnington Park | AO10: Donnington Park | AP10: Great Britain | AQ10: 90 Mins | AR10: Jul 9 | AU10: R6 | AW10: 1000km of Suzuka | AX10: Suzuka Circuit | AY10: Japan | AZ10: 1000km | BA10: B | BB10: Oct 8 | BE10: R6 | BG10: ASM 150 Minutes of Charlotte | BH10: Charlotte Motor Speedway Roval | BI10: United States | BJ10: 150 Mins | BK10: Aug 13
H11: R7 | J11: 6 Hours of Fuji | K11: Fuji Speedway | L11: Japan | M11: 6 Hours | N11: B | O11: Oct 28 | R11: R7 | T11: Mosport Showdown | U11: Canadian Tire Motorsport Park | V11: Canada | W11: 160 Mins | X11: S | Y11: LMP2, GTLM | Z11: July 15 | AC11: R7 | AE11: 4 Hours of Portimao | AF11: Autodromo Internacional do Algarve | AG11: Portugal | AH11: 4 Hours | AI11: Sept 2 | AL11: R7 | AN11: World GT Sprint Series at Misano World Circuit | AO11: Misano World Circuit Marco Simoncelli | AP11: Italy | AQ11: 90 Mins | AR11: Jul 30 | AU11: R7 | AW11: 9 Hours of Kyalami | AX11: Kyalami Grand Prix Circuit | AY11: South Africa | AZ11: 9 Hours | BA11: B | BB11: Dec 3 | BE11: R7 | BG11: ASM 150 Minutes of Watkins Glen | BH11: Watkins Glen International | BI11: United States | BJ11: 150 Mins | BK11: Sep 3
H12: R8 | J12: 8 Hours of Bahrain | K12: Bahrain International Circuit | L12: Bahrain | M12: 8 Hours | N12: B | O12: Nov 18 | R12: R8 | T12: American Sportscar Classic | U12: Road America | V12: United States | W12: 6 Hours | X12: E, EC | Y12: All | Z12: Aug 5 | AC12: R8 | AE12: 4 Hours of Sepang | AF12: Sepang International Circuit | AG12: Malaysia | AH12: 4 Hours | AI12: Oct 14 | AL12: R8 | AN12: World GT Sprint Series at Portimao | AO12: Autodromo Internacional do Algarve | AP12: Portugal | AQ12: 90 Mins | AR12: Aug 27 | BE12: R8 | BG12: ASM 150 Minutes of VIR | BH12: Virginia International Raceway | BI12: United States | BJ12: 150 Mins | BK12: Oct 1
R13: R9 | T13: Grand Prix of Texas | U13: Circuit of The Americas | V13: United States | W13: 160 Mins | X13: S | Y13: All | Z13: Aug 19 | AC13: R9 | AE13: 4 Hours of Buddh | AF13: Buddh International Circuit | AG13: India | AH13: 4 Hours | AI13: Nov 4 | AL13: R9 | AN13: World GT Sprint Series in India | AO13: Buddh International Circuit | AP13: India | AQ13: 90 Mins | AR13: Oct 8 | BE13: R9 | BG13: ASM 210 Minutes of CoTA | BH13: Circuit of The Americas | BI13: United States | BJ13: 210 Mins | BK13: Oct 29
R14: R10 | T14: Motul Course de Monterey | U14: WeatherTech Raceway Laguna Seca | V14: United States | W14: 160 Mins | X14: S | Y14: DPi, GT | Z14: Sept 9 | AL14: R10 | AN14: World GT Sprint Series in Korea | AO14: Korea International Circuit | AP14: South Korea | AQ14: 90 Mins | AR14: Oct 29
R15: R11 | T15: Grand Prix of Lime Rock | U15: Lime Rock Park | V15: United States | W15: 160 Mins | X15: S | Y15: DPi, GT | Z15: Sept 30 | AL15: R11 | AN15: World GT Sprint Series at The Gold Coast | AO15: Surfers Paradise Street Circuit | AP15: Australia | AQ15: 2 Hrs | AR15: Nov 19
R16: R12 | T16: Petit Le Mans | U16: Road Atlanta | V16: United States | W16: 10 Hours | X16: E, EC | Y16: All | Z16: Oct 14

Sheet Calendars (2)
B2: Team Creator V10 - 2018 | H2: Team Creator V10 - 2018 | R2: Team Creator V10 - 2018 | AC2: Team Creator V10 - 2018 | AL2: Team Creator V10 - 2018 | AU2: Team Creator V10 - 2018 | BE2: Team Creator V10 - 2018
B3: Permitted One Off Entries | H3: Series Calendar | L3: Global Endurance Masters | R3: Series Calendar | W3: North American Sportscar Championship | AC3: Series Calendar | AG3: Eurasian Endurance Masters | AL3: Series Calendar | AP3: World GT Sprint Series | AU3: Series Calendar | AY3: World GT Masters | BE3: Series Calendar | BI3: American Sportscar Masters
B4: Rd No | C4: Title | E4: Notes | H4: Rd No | I4: Title | K4: Track | M4: Length | N4: Points | O4: Date | R4: Rd No | S4: Title | U4: Track | W4: Length | X4: Points | Y4: Classes | Z4: Date | AC4: Rd No | AD4: Title | AF4: Track | AH4: Length | AI4: Date | AL4: Rd No | AM4: Title | AO4: Track | AQ4: Length | AR4: Date | AU4: Rd No | AV4: Title | AX4: Track | AZ4: Length | BA4: Points | BB4: Date | BE4: Rd No | BF4: Title | BH4: Track | BJ4: Length | BK4: Date
B5: GEM | D5: 24 Heures du Mans | E5: Invite + Application | H5: R1 | J5: 8 Hours of Silverstone | K5: Silverstone Circuit | L5: Great Britain | M5: 8 Hours | N5: B | O5: April 15 | R5: R1 | T5: Rolex 24 at Daytona | U5: Daytona International Speedway | V5: United States | W5: 24 Hours | X5: R24, EC | Y5: All | Z5: Jan 27-28 | AC5: R1 | AE5: 4 Hours of Buriram | AF5: Buriram International Circuit | AG5: Thailand | AH5: 4 Hours | AI5: Jan 14 | AL5: R1 | AN5: World GT Sprint Series at Sepang | AO5: Sepang International Circuit | AP5: Malaysia | AQ5: 90 Mins | AR5: Mar 5 | AU5: R1 | AW5: Bathurst 12 Hours | AX5: Mount Panorama | AY5: Australia | AZ5: 12 Hours | BA5: B | BB5: Feb 5 | BE5: R1 | BG5: ASM 150 Minutes of VIR | BH5: Virginia International Raceway | BI5: United States | BJ5: 150 Mins | BK5: Apr 2
B6: NASCC | D6: Rolex 24 at Daytona | E6: Application | H6: R2 | J6: 6 Hours of Spa | K6: Circuit de Spa-Francorshamps | L6: Belgium | M6: 6 Hours | N6: B | O6: May 5 | R6: R2 | T6: 12 Hours of Sebring | U6: Sebring International Raceway | V6: United States | W6: 12 Hours | X6: E, EC | Y6: All | Z6: March 18 | AC6: R2 | AE6: 4 Hours of The Bend | AF6: The Bend Motorsports Park | AG6: Australia | AH6: 4 Hours | AI6: Feb 25 | AL6: R2 | AN6: World GT Sprint Series at Shanghai | AO6: Shanghai International Circuit | AP6: China | AQ6: 90 Mins | AR6: Mar 26 | AU6: R2 | AW6: 8 Hours of Road America | AX6: Road America | AY6: United States | AZ6: 8 Hours | BA6: B | BB6: Apr 9 | BE6: R2 | BG6: ASM 150 Minutes of Sebring | BH6: Sebring International Raceway | BI6: United States | BJ6: 150 Mins | BK6: May 7
B7: NASCC | D7: 12 Hours of Sebring | E7: Application | H7: R3 | J7: 24 Heures du Mans | K7: Circuit de la Sarthe | L7: France | M7: 24 Hours | N7: A | O7: June 16-17 | R7: R3 | T7: Acura Grand Prix of Long Beach | U7: Streets of Long Beach | V7: United States | W7: 100 Mins | X7: S | Y7: DPi, GTD | Z7: April 7 | AC7: R3 | AE7: 4 Hours of Silverstone | AF7: Silverstone Circuit | AG7: Great Britain | AH7: 4 Hours | AI7: April 14 | AL7: R3 | AN7: World GT Sprint Series at Laguna Seca | AO7: WeatherTech Raceway Laguna Seca | AP7: United States | AQ7: 90 Mins | AR7: Apr 30 | AU7: R3 | AW7: 24 Hours of The Nurburgring | AX7: Nurburgring Nordschleiffe | AY7: Germany | AZ7: 24 Hours | BA7: A | BB7: May 28 | BE7: R3 | BG7: ASM 150 Minutes of Daytona | BH7: Daytona International Speedway | BI7: United States | BJ7: 150 Mins | BK7: May 21
B8: NASCC | D8: Petit Le Mans | E8: Application | H8: R4 | J8: 8 Hours of The Nurburgring | K8: Nurburgring | L8: Germany | M8: 8 Hours | N8: B | O8: July 15 | R8: R4 | T8: Mexico City Grand Prix | U8: Autodromo Hermanos Rodriguez | V8: Mexico | W8: 160 Mins | X8: S | Y8: All | Z8: April 29 | AC8: R4 | AE8: 4 Hours of Paul Ricard | AF8: Circuit Paul Ricard | AG8: France | AH8: 4 Hours | AI8: May 13 | AL8: R4 | AN8: World GT Sprint Series at Circuit Zolder | AO8: Circuit Zolder | AP8: Netherlands | AQ8: 90 Mins | AR8: Jun 4 | AU8: R4 | AW8: 24 Hours of Spa | AX8: Circuit de Spa-Francorshamps | AY8: Belgium | AZ8: 24 Hours | BA8: A | BB8: Jul 30 | BE8: R4 | BG8: ASM 150 Minutes of Laguna Seca | BH8: WeatherTech Raceway Laguna Seca | BI8: United States | BJ8: 150 Mins | BK8: Jun 25
B9: WGTSS | D9: World GT Sprint Series at Le Mans | E9: Application | H9: R5 | J9: Lonestar Le Mans | K9: Circuit of The Americas | L9: United States | M9: 6 Hours | N9: B | O9: Sept 9 | R9: R5 | T9: Michelin Grand Prix at VIR | U9: Virginia International Raceway | V9: United States | W9: 160 Mins | X9: S | Y9: LMP2, GT | Z9: May 20 | AC9: R5 | AE9: 4 Hours of Imola | AF9: Imola Circuit | AG9: Italy | AH9: 4 Hours | AI9: June 24 | AL9: R5 | AN9: World GT Sprint Series at Le Mans | AO9: Circuit de la Sarthe | AP9: France | AQ9: 2 Hrs | AR9: Jun 16 | AU9: R5 | AW9: 8 Hours of Indianapolis | AX9: Indianapolis Motor Speedway RC | AY9: United States | AZ9: 8 Hours | BA9: B | BB9: Aug 27 | BE9: R5 | BG9: ASM 150 Minutes of CTMP | BH9: Canadian Tire Motorsport Park | BI9: Canada | BJ9: 150 Mins | BK9: Jul 16
B10: WGTM | D10: Bathurst 12 Hours | E10: Application | H10: R6 | J10: 6 Hours of Kyalami | K10: Kyalami Circuit | L10: South Africa | M10: 6 Hours | N10: B | O10: Oct 7 | R10: R6 | T10: Sahlen's 6 Hours of The Glen | U10: Watkins Glen International | V10: United States | W10: 6 Hours | X10: E, EC | Y10: All | Z10: July 1 | AC10: R6 | AE10: 4 Hours of Aragon | AF10: Motorland Aragon | AG10: Spain | AH10: 4 Hours | AI10: Aug 5 | AL10: R6 | AN10: World GT Sprint Series at Donnington Park | AO10: Donnington Park | AP10: Great Britain | AQ10: 90 Mins | AR10: Jul 9 | AU10: R6 | AW10: 1000km of Suzuka | AX10: Suzuka Circuit | AY10: Japan | AZ10: 1000km | BA10: B | BB10: Oct 8 | BE10: R6 | BG10: ASM 150 Minutes of Charlotte | BH10: Charlotte Motor Speedway Roval | BI10: United States | BJ10: 150 Mins | BK10: Aug 13
B11: WGTM | D11: 24 Hours of The Nurburgring | E11: Application | H11: R7 | J11: 6 Hours of Fuji | K11: Fuji Speedway | L11: Japan | M11: 6 Hours | N11: B | O11: Oct 28 | R11: R7 | T11: Mosport Showdown | U11: Canadian Tire Motorsport Park | V11: Canada | W11: 160 Mins | X11: S | Y11: LMP2, GTLM | Z11: July 15 | AC11: R7 | AE11: 4 Hours of Portimao | AF11: Autodromo Internacional do Algarve | AG11: Portugal | AH11: 4 Hours | AI11: Sept 2 | AL11: R7 | AN11: World GT Sprint Series at Misano World Circuit | AO11: Misano World Circuit Marco Simoncelli | AP11: Italy | AQ11: 90 Mins | AR11: Jul 30 | AU11: R7 | AW11: 9 Hours of Kyalami | AX11: Kyalami Grand Prix Circuit | AY11: South Africa | AZ11: 9 Hours | BA11: B | BB11: Dec 3 | BE11: R7 | BG11: ASM 150 Minutes of Watkins Glen | BH11: Watkins Glen International | BI11: United States | BJ11: 150 Mins | BK11: Sep 3
B12: WGTM | D12: 24 Hours of Spa | E12: Application | H12: R8 | J12: 8 Hours of Bahrain | K12: Bahrain International Circuit | L12: Bahrain | M12: 8 Hours | N12: B | O12: Nov 18 | R12: R8 | T12: American Sportscar Classic | U12: Road America | V12: United States | W12: 6 Hours | X12: E, EC | Y12: All | Z12: Aug 5 | AC12: R8 | AE12: 4 Hours of Sepang | AF12: Sepang International Circuit | AG12: Malaysia | AH12: 4 Hours | AI12: Oct 14 | AL12: R8 | AN12: World GT Sprint Series at Portimao | AO12: Autodromo Internacional do Algarve | AP12: Portugal | AQ12: 90 Mins | AR12: Aug 27 | BE12: R8 | BG12: ASM 150 Minutes of VIR | BH12: Virginia International Raceway | BI12: United States | BJ12: 150 Mins | BK12: Oct 1
B13: ASM | D13: ASM 210 Minutes of CoTA | E13: Application | R13: R9 | T13: Grand Prix of Texas | U13: Circuit of The Americas | V13: United States | W13: 160 Mins | X13: S | Y13: All | Z13: Aug 19 | AC13: R9 | AE13: 4 Hours of Buddh | AF13: Buddh International Circuit | AG13: India | AH13: 4 Hours | AI13: Nov 4 | AL13: R9 | AN13: World GT Sprint Series in India | AO13: Buddh International Circuit | AP13: India | AQ13: 90 Mins | AR13: Oct 8 | BE13: R9 | BG13: ASM 210 Minutes of CoTA | BH13: Circuit of The Americas | BI13: United States | BJ13: 210 Mins | BK13: Oct 29
R14: R10 | T14: Motul Course de Monterey | U14: WeatherTech Raceway Laguna Seca | V14: United States | W14: 160 Mins | X14: S | Y14: DPi, GT | Z14: Sept 9 | AL14: R10 | AN14: World GT Sprint Series in Korea | AO14: Korea International Circuit | AP14: South Korea | AQ14: 90 Mins | AR14: Oct 29
R15: R11 | T15: Grand Prix of Lime Rock | U15: Lime Rock Park | V15: United States | W15: 160 Mins | X15: S | Y15: DPi, GT | Z15: Sept 30 | AL15: R11 | AN15: World GT Sprint Series at The Gold Coast | AO15: Surfers Paradise Street Circuit | AP15: Australia | AQ15: 2 Hrs | AR15: Nov 19
R16: R12 | T16: Petit Le Mans | U16: Road Atlanta | V16: United States | W16: 10 Hours | X16: E, EC | Y16: All | Z16: Oct 14

Sheet Car Purchase
B2: Team Creator V10 - 2018 | H2: Team Creator V10 - 2018
B3: Car Purchase | H3: Spares Purchase
B4: Given ID | C4: Platform | D4: Model Name | E4: Notes | H4: Platform | I4: Model Name | J4: Chassis | K4: Powertrain | L4: Spares | O4: Selected Tyre Suppliers
B5: DPi_1 | C5: =IF(D5 <> "", VLOOKUP(D5, modelData, 2, FALSE), "") -> DPi | D5: Acura ARX-05 | H5: =IF(AND(I5 <> "", I5 <> 0), VLOOKUP(I5, modelData, 2, FALSE), "") -> DPi | I5: {=IF(_xlfn.UNIQUE(D5:D49, 0, FALSE) = 0, "", _xlfn.UNIQUE(D5:D49, 0, FALSE))} -> Acura ARX-05 | O5: Global Endurance Masters
B6: DPi_2 | C6: =IF(D6 <> "", VLOOKUP(D6, modelData, 2, FALSE), "") -> DPi | D6: Cadillac DPi-V.R | H6: =IF(AND(I6 <> "", I6 <> 0), VLOOKUP(I6, modelData, 2, FALSE), "") -> DPi | I6: Cadillac DPi-V.R | O6: Class | P6: Tyre Supplier
B7: DPi_3 | C7: =IF(D7 <> "", VLOOKUP(D7, modelData, 2, FALSE), "") -> DPi | D7: Mazda RT24-P | H7: =IF(AND(I7 <> "", I7 <> 0), VLOOKUP(I7, modelData, 2, FALSE), "") -> DPi | I7: Mazda RT24-P | O7: LMP1 | P7: Michelin
B8: DPi_4 | C8: =IF(D8 <> "", VLOOKUP(D8, modelData, 2, FALSE), "") -> DPi | D8: Nissan Onroak DPi | H8: =IF(AND(I8 <> "", I8 <> 0), VLOOKUP(I8, modelData, 2, FALSE), "") -> DPi | I8: Nissan Onroak DPi | O8: LMP2
B9: LMP1_1 | C9: =IF(D9 <> "", VLOOKUP(D9, modelData, 2, FALSE), "") -> LMP1-L | D9: BR Engineering BR1 | H9: =IF(AND(I9 <> "", I9 <> 0), VLOOKUP(I9, modelData, 2, FALSE), "") -> LMP1-L | I9: BR Engineering BR1 | O9: LMGTE PRO
B10: LMP1_2 | C10: =IF(D10 <> "", VLOOKUP(D10, modelData, 2, FALSE), "") -> LMP1-L | D10: ENSO CLM P1/01 | H10: =IF(AND(I10 <> "", I10 <> 0), VLOOKUP(I10, modelData, 2, FALSE), "") -> LMP1-L | I10: ENSO CLM P1/01 | O10: LMGTE AM
B11: LMP1_3 | C11: =IF(D11 <> "", VLOOKUP(D11, modelData, 2, FALSE), "") -> LMP1-L | D11: Ginetta G60-LT-P1 | H11: =IF(AND(I11 <> "", I11 <> 0), VLOOKUP(I11, modelData, 2, FALSE), "") -> LMP1-L | I11: Ginetta G60-LT-P1 | O11: NASCC
B12: LMP1_4 | C12: =IF(D12 <> "", VLOOKUP(D12, modelData, 2, FALSE), "") -> LMP1-L | D12: Rebellion R13 | H12: =IF(AND(I12 <> "", I12 <> 0), VLOOKUP(I12, modelData, 2, FALSE), "") -> LMP1-L | I12: Rebellion R13 | O12: Class | P12: Tyre Supplier
B13: LMP1_5 | C13: =IF(D13 <> "", VLOOKUP(D13, modelData, 2, FALSE), "") -> LMP1-H | D13: Porsche 919 Hybrid | H13: =IF(AND(I13 <> "", I13 <> 0), VLOOKUP(I13, modelData, 2, FALSE), "") -> LMP1-H | I13: Porsche 919 Hybrid | O13: DPi | P13: Michelin
B14: LMP1_6 | C14: =IF(D14 <> "", VLOOKUP(D14, modelData, 2, FALSE), "") -> LMP1-H | D14: Toyota TS050 - Hybrid | H14: =IF(AND(I14 <> "", I14 <> 0), VLOOKUP(I14, modelData, 2, FALSE), "") -> LMP1-H | I14: Toyota TS050 - Hybrid | O14: LMP2
C15: =IF(D15 <> "", VLOOKUP(D15, modelData, 2, FALSE), "") | H15: =IF(AND(I15 <> "", I15 <> 0), VLOOKUP(I15, modelData, 2, FALSE), "") | O15: GTLM
C16: =IF(D16 <> "", VLOOKUP(D16, modelData, 2, FALSE), "") | H16: =IF(AND(I16 <> "", I16 <> 0), VLOOKUP(I16, modelData, 2, FALSE), "") | O16: GTD
C17: =IF(D17 <> "", VLOOKUP(D17, modelData, 2, FALSE), "") | H17: =IF(AND(I17 <> "", I17 <> 0), VLOOKUP(I17, modelData, 2, FALSE), "") | O17: EuEM
C18: =IF(D18 <> "", VLOOKUP(D18, modelData, 2, FALSE), "") | H18: =IF(AND(I18 <> "", I18 <> 0), VLOOKUP(I18, modelData, 2, FALSE), "") | O18: Class | P18: Tyre Supplier
C19: =IF(D19 <> "", VLOOKUP(D19, modelData, 2, FALSE), "") | H19: =IF(AND(I19 <> "", I19 <> 0), VLOOKUP(I19, modelData, 2, FALSE), "") | O19: LMP2
C20: =IF(D20 <> "", VLOOKUP(D20, modelData, 2, FALSE), "") | H20: =IF(AND(I20 <> "", I20 <> 0), VLOOKUP(I20, modelData, 2, FALSE), "") | O20: LMP3 | P20: Michelin
C21: =IF(D21 <> "", VLOOKUP(D21, modelData, 2, FALSE), "") | H21: =IF(AND(I21 <> "", I21 <> 0), VLOOKUP(I21, modelData, 2, FALSE), "") | O21: LMGTE
C22: =IF(D22 <> "", VLOOKUP(D22, modelData, 2, FALSE), "") | H22: =IF(AND(I22 <> "", I22 <> 0), VLOOKUP(I22, modelData, 2, FALSE), "")
C23: =IF(D23 <> "", VLOOKUP(D23, modelData, 2, FALSE), "") | H23: =IF(AND(I23 <> "", I23 <> 0), VLOOKUP(I23, modelData, 2, FALSE), "")
C24: =IF(D24 <> "", VLOOKUP(D24, modelData, 2, FALSE), "") | H24: =IF(AND(I24 <> "", I24 <> 0), VLOOKUP(I24, modelData, 2, FALSE), "")
C25: =IF(D25 <> "", VLOOKUP(D25, modelData, 2, FALSE), "") | H25: =IF(AND(I25 <> "", I25 <> 0), VLOOKUP(I25, modelData, 2, FALSE), "")
C26: =IF(D26 <> "", VLOOKUP(D26, modelData, 2, FALSE), "") | H26: =IF(AND(I26 <> "", I26 <> 0), VLOOKUP(I26, modelData, 2, FALSE), "")
C27: =IF(D27 <> "", VLOOKUP(D27, modelData, 2, FALSE), "") | H27: =IF(AND(I27 <> "", I27 <> 0), VLOOKUP(I27, modelData, 2, FALSE), "")
C28: =IF(D28 <> "", VLOOKUP(D28, modelData, 2, FALSE), "") | H28: =IF(AND(I28 <> "", I28 <> 0), VLOOKUP(I28, modelData, 2, FALSE), "")
C29: =IF(D29 <> "", VLOOKUP(D29, modelData, 2, FALSE), "") | H29: =IF(AND(I29 <> "", I29 <> 0), VLOOKUP(I29, modelData, 2, FALSE), "")
C30: =IF(D30 <> "", VLOOKUP(D30, modelData, 2, FALSE), "") | H30: =IF(AND(I30 <> "", I30 <> 0), VLOOKUP(I30, modelData, 2, FALSE), "")
C31: =IF(D31 <> "", VLOOKUP(D31, modelData, 2, FALSE), "") | H31: =IF(AND(I31 <> "", I31 <> 0), VLOOKUP(I31, modelData, 2, FALSE), "")
C32: =IF(D32 <> "", VLOOKUP(D32, modelData, 2, FALSE), "") | H32: =IF(AND(I32 <> "", I32 <> 0), VLOOKUP(I32, modelData, 2, FALSE), "")
C33: =IF(D33 <> "", VLOOKUP(D33, modelData, 2, FALSE), "") | H33: =IF(AND(I33 <> "", I33 <> 0), VLOOKUP(I33, modelData, 2, FALSE), "")
... C49: =IF(D49 <> "", VLOOKUP(D49, modelData, 2, FALSE), "") | H49: =IF(AND(I49 <> "", I49 <> 0), VLOOKUP(I49, modelData, 2, FALSE), "")

Sheet Full Season Entries
B2: Team Creator V10 - 2018
B3: Full Season Entries | X3: Team Creator V10 - 2018
B4: Entry No | C4: Series Information | E4: Entry Details | H4: Car Model Details | K4: Driver Details | P4: Entrant Setup Bonuses | U4: Total Costs | X4: Full Season Entries | AA4: Car Model Fetching | AF4: Class Fetching
C5: Series Name | D5: Class | E5: Car No | F5: Team Name | G5: Tyre Supplier | H5: Model ID | I5: Platform | J5: Model Name | K5: Driver 1 | L5: Driver 2 | M5: Driver 3 | N5: Driver 4 | O5: Legality | P5: Setup | T5: Reliability | X5: Usage Guide | AA5: Platform | AB5: Model Name | AD5: Tyre Supplier | AF5: Indices | AH5: Rough | AI5: Final | AN5: Lineup Legality | AP5: Entry Costs
